01-21 19:14:41 gphotos.Main WARNING  gphotos-sync 2.14.2 2022-01-21 19:14:41.706622
01-21 19:14:41 gphotos.Utils DEBUG    MINIMUM_DATE = 1800-01-01 00:00:00
01-21 19:14:41 gphotos.Checks INFO     Target filesystem /data is fuse.grpcfuse
01-21 19:14:41 gphotos.Checks DEBUG    Checking if is filesystem supports symbolic links...
01-21 19:14:41 gphotos.Checks DEBUG    attempting to symlink /data/test_src_3313292237 to /data/test_dst_2527586457
01-21 19:14:41 gphotos.Checks DEBUG    Checking if File system supports unicode filenames...
01-21 19:14:41 gphotos.Checks INFO     Filesystem supports Unicode filenames
01-21 19:14:41 gphotos.Checks DEBUG    Checking if File system is case insensitive...
01-21 19:14:41 gphotos.Checks INFO     Case insensitive file system found
01-21 19:14:41 gphotos.Checks INFO     Max Path Length: 4096
01-21 19:14:41 gphotos.Checks INFO     Max filename length: 255
01-21 19:14:41 gphotos.Main INFO     version: 2.14.2, database schema version 5.7
01-21 19:14:42 gphotos.LocalData INFO     Saving Database ...
01-21 19:14:42 gphotos.LocalData INFO     Database Saved.
01-21 19:14:42 gphotos.LocalData INFO     Saving Database ...
01-21 19:14:42 gphotos.LocalData INFO     Database Saved.
01-21 19:14:42 gphotos.Main ERROR    
Process failed.
Traceback (most recent call last):
  File "/opt/venv/lib/python3.10/site-packages/gphotos/authorize.py", line 44, in __init__
    with secrets_file.open("r") as stream:
  File "/usr/local/lib/python3.10/pathlib.py", line 1117, in open
    return self._accessor.open(self, mode, buffering, encoding, errors,
IsADirectoryError: [Errno 21] Is a directory: '/data'

During handling of the above exception, another exception occurred:

Traceback (most recent call last):
  File "/opt/venv/lib/python3.10/site-packages/gphotos/Main.py", line 417, in main
    self.setup(args, db_path)
  File "/opt/venv/lib/python3.10/site-packages/gphotos/Main.py", line 281, in setup
    self.auth = Authorize(
  File "/opt/venv/lib/python3.10/site-packages/gphotos/authorize.py", line 58, in __init__
    exit(1)
  File "/usr/local/lib/python3.10/_sitebuiltins.py", line 26, in __call__
    raise SystemExit(code)
SystemExit: 1
01-21 19:14:42 gphotos.Main WARNING  Done.
01-21 19:14:42 gphotos.Main INFO     Elapsed time = 0:00:00.325476
